Workbook
Name CreateSearchString: _xlfn.LAMBDA(_xlpm._in,IF(_xlpm._in="","",","&SUBSTITUTE(SUBSTITUTE(_xlpm._in,CHAR(10),"")," ","")&IF(RIGHT(_xlpm._in,1)=",","",",")))
Name EscapeString: _xlfn.LAMBDA(_xlpm._string,SUBSTITUTE(_xlpm._string,CHAR(34),"'"))
Name GenerateRationale: _xlfn.LAMBDA(_xlpm._in, OFFSET(_xlpm._in,0,0)&": "&CHAR(10)& OFFSET(_xlpm._in,0,1)&": "&CHAR(10)& OFFSET(_xlpm._in,0,2)&": "&CHAR(10)& OFFSET(_xlpm._in,0,3)&": "&CHAR(10)& OFFSET(_xlpm._in,0,4)&": ")
Name GetReferenceText: _xlfn.LAMBDA(_xlpm._reference, _xlfn.LET( _xlpm._full,CELL("address",_xlpm._reference),"'"&SUBSTITUTE(SUBSTITUTE(RIGHT(_xlpm._full,LEN(_xlpm._full)-FIND("]",_xlpm._full)),"'!","!"),"!","'!")))
Name GetSheetName: _xlfn.LAMBDA(_xlpm._shadowIDHeader, _xlfn.LET( _xlpm._sheetAddress,CELL("filename",_xlpm._shadowIDHeader), RIGHT(_xlpm._sheetAddress,LEN(_xlpm._sheetAddress)-FIND("]",_xlpm._sheetAddress))))
Name JSON_Questionnaire: JSON!$C$7
Name JSON_ResultSummary: JSON!$C$9
Name JSON_RiskTreatment: JSON!$C$8
Name LookupNames: _xlfn.LAMBDA(_xlpm._in,_xlpm._range,RemoveDelimiter(GetValues(SanitizeInput(_xlpm._in),_xlpm._range," ",","&CHAR(10),TRUE),","&CHAR(10)))
Name PrintDate: _xlfn.LAMBDA(_xlpm._date,TEXT(DAY(_xlpm._date),"00")&"."&TEXT(MONTH(_xlpm._date),"00")&"."&TEXT(YEAR(_xlpm._date),"0000"))
Name RemoveDelimiter: _xlfn.LAMBDA(_xlpm._in,_xlpm._delimiter,IF(_xlpm._in="","",SUBSTITUTE(SUBSTITUTE(_xlpm._in&CHAR(1),_xlpm._delimiter&CHAR(1),""),CHAR(1),"")))
Name RemoveFirstElement: _xlfn.LAMBDA(_xlpm._in,IF(_xlpm._in="","",SUBSTITUTE(SUBSTITUTE(SUBSTITUTE("#"&_xlpm._in,",",",#"),"#"&LEFT(_xlpm._in,FIND(",",_xlpm._in)),""),"#","")))
Name SanitizeInput: _xlfn.LAMBDA(_xlpm._in,IF(_xlpm._in="","",SUBSTITUTE(SUBSTITUTE(_xlpm._in,CHAR(10),"")," ","")&IF(RIGHT(_xlpm._in,1)=",","",",")))
Name SimpleLookup: _xlfn.LAMBDA(_xlpm._id,_xlpm._range,VLOOKUP(_xlpm._id,_xlpm._range,COLUMNS(_xlpm._range),FALSE))
Name SimpleLookupWithErrorMessage: _xlfn.LAMBDA(_xlpm._searchFor,_xlpm._searchRange,IFERROR(VLOOKUP(_xlpm._searchFor,_xlpm._searchRange,COLUMNS(_xlpm._searchRange),FALSE),"ERROR: Unknown ID: "&_xlpm._searchFor))

Sheet License
A2: Questionnaire-Based Assessment (QuBA) © 2025 by SICK AG and Fraunhofer-Institut für Angewandte und Integrierte Sicherheit AISEC is licensed under CC BY-SA 4.0. To view a copy of this license, visit https://creativecommons.org/licenses/by-sa/4.0/

Sheet README
A1: Quick Start Guide (See below for more detailed explanations)
B2: {=HYPERLINK("#"&GetReferenceText(Definitions!$C$4),"(0) Tailor the assessment model and the catalogs.")} -> (0) Tailor the assessment model and the catalogs.
B3: Make sure you tailor the document, especially the assessment model contained in the Definitions sheet and the catalogs, to your organization. For example, adapt the exemplary risk matrix to a matrix that fits your organization and its context.
B4: {=HYPERLINK("#"&GetReferenceText(Documentation!$C$2),"(1) Provide basic information in the Documentation sheet.")} -> (1) Provide basic information in the Documentation sheet.
B5: {=HYPERLINK("#"&GetReferenceText(Questionnaire!$D$6),"(2) Answer the questions in the Questionnaire sheet. Fill all marked boxes.")} -> (2) Answer the questions in the Questionnaire sheet. Fill all marked boxes.
B6: {=HYPERLINK("#"&GetReferenceText(Risks!$A$2),"(3) Ensure that the table in the Risks sheet is large enough to calculate all attack paths.")} -> (3) Ensure that the table in the Risks sheet is large enough to calculate all attack paths.
B7: If the message "Please enlarge the table to calculate all risks!" is displayed, then follow these steps: (1) Click on the blue triangle in the bottom right corner of the table, above the area colored in red. (2) Hold the left mouse button and drag the mouse downward until the red area is covered.
B8: {=HYPERLINK("#"&GetReferenceText(Mitigation!$J$3),"(4) Assign assumptions and countermeasures mitigating specific attack steps in the Mitigation sheet.")} -> (4) Assign assumptions and countermeasures mitigating specific attack steps in the Mitigation sheet.
B9: Recommendation: Copy the column Proposed Active Assumptions and paste as values into the column C and A IDs. These assumptions match the answers provided in the questionnaire. See below for additional information.
B10: {=HYPERLINK("#"&GetReferenceText('Risk Treatment'!$A$5),"(5) Make risk treatment decisions in the Risk Treatment sheet.")} -> (5) Make risk treatment decisions in the Risk Treatment sheet.
A12: General Remarks
B13: * Whenever several items can be referenced, use comma-separated lists, denoted as CSV in the explanations below.
B14: * Some cells are restricted to choosing from a pre-defined list of options, denoted by drop-down menu in the explanations below.
B15: * All comment columns that accept text can be used with the Tasks feature (see the explanation for the Tasks sheet).
B16: * When copying, always paste as values!
B17: * For all questions that contain several criteria (e.g., "Is the access to the network restricted and are the devices in the network considered as trustworthy?":
B18: Only select "Yes" as an answer if all criteria a true (in this case, access is restricted and the devices are trustworthy).
A20: Sheet Color | B20: Explanation
A21: Black | B21: This readme, the answering guideline, and the version history.
A22: Light Grey | B22: Catalogs - these are versioned and centrally managed. Do not edit during an analysis.
A23: Dark Grey | B23: Fill these sheets to complete the analysis.
A24: Blue | B24: Calculation and presentation of results.
A25: Green | B25: The summary of the resulting assumptions and countermeasures, including IDs for the external catalog, if available.
A27: Text Format | B27: Explanation
A28: White | B28: Contents of the analysis or the template. May be text or a formula.
A29: Green | B29: Calculated values, do not edit as the formula is included in template version management.
A30: Light Green | B30: The target of a link from the Tasks sheet (typically a TODO).
A31: Light Green | B31: A link.
A32: Lime | B32: On this README sheet in the table below: Highlights the sheets that must be filled in an analysis.
A34: Detailed explanations for each sheet
A35: Sheet | B35: Column | C35: Explanation | D35: Comment | E35: Sheet Name | F35: Column Letter | G35: Header Row | H35: Sheet # | I35: Column Original Name | K35: Column Header Address | L35: Explicit Link Text | M35: Additional information
A36: {=IF(INDEX($H:$H,ROW()-1)<>$H36,$E36,"")} -> Version History | B36: {=IF($K36="","",_xlfn.LET( _xlpm._fullName,IF($L36="",SUBSTITUTE(SUBSTITUTE(INDIRECT($K36),CHAR(10)," ")," "," "),$L36), _xlpm._truncatedName,IF(LEN(_xlpm._fullName)>250,LEFT(_xlpm._fullName,250)&"[…]",_xlpm._fullName), HYPERLINK("#'"&$E36&"'!"&$F36&$G36, _xlpm._truncatedName)))} -> Template Version History | C36: A version history for the template (independent of the assessment). | E36: =IF($K36="","",_xlfn.LET( _xlpm._in,$K36, _xlpm._start,FIND("]",_xlpm._in)+1, SUBSTITUTE(MID(_xlpm._in,_xlpm._start,FIND("!",_xlpm._in)-_xlpm._start),"'",""))) -> Version History | F36: =IF($K36="","",_xlfn.LET( _xlpm._in,SUBSTITUTE($K36,"$","§",1), _xlpm._start,FIND("§",_xlpm._in)+1, SUBSTITUTE(MID(_xlpm._in,_xlpm._start,FIND("$",_xlpm._in)-_xlpm._start),"'",""))) -> B | G36: =IF($K36="","",RIGHT($K36,LEN($K36)-FIND("$",SUBSTITUTE($K36,"$","§",1)))) -> 1 | H36: {=CreateID($H$35,$E36<>INDEX($E:$E,ROW()-1))} -> 1 | I36: {=INDIRECT($K36)} -> Template Version History | K36: {=CELL("address",'Version History'!$B$1)} -> '[QuBA-libre.xlsx]Version History'!$B$1
A37: {=IF(INDEX($H:$H,ROW()-1)<>$H37,$E37,"")} | B37: {=IF($K37="","",_xlfn.LET( _xlpm._fullName,IF($L37="",SUBSTITUTE(SUBSTITUTE(INDIRECT($K37),CHAR(10)," ")," "," "),$L37), _xlpm._truncatedName,IF(LEN(_xlpm._fullName)>250,LEFT(_xlpm._fullName,250)&"[…]",_xlpm._fullName), HYPERLINK("#'"&$E37&"'!"&$F37&$G37, _xlpm._truncatedName)))} -> Definitions and Damage Scenarios Version History | C37: A version history for the Definitions sheet. Note that this usually relates to changes in the assessment model. | E37: =IF($K37="","",_xlfn.LET( _xlpm._in,$K37, _xlpm._start,FIND("]",_xlpm._in)+1, SUBSTITUTE(MID(_xlpm._in,_xlpm._start,FIND("!",_xlpm._in)-_xlpm._start),"'",""))) -> Version History | F37: =IF($K37="","",_xlfn.LET( _xlpm._in,SUBSTITUTE($K37,"$","§",1), _xlpm._start,FIND("§",_xlpm._in)+1, SUBSTITUTE(MID(_xlpm._in,_xlpm._start,FIND("$",_xlpm._in)-_xlpm._start),"'",""))) -> B | G37: =IF($K37="","",RIGHT($K37,LEN($K37)-FIND("$",SUBSTITUTE($K37,"$","§",1)))) -> 6 | H37: {=CreateID($H$35,$E37<>INDEX($E:$E,ROW()-1))} -> 1 | I37: {=INDIRECT($K37)} -> Definitions and Damage Scenarios Version History | K37: {=CELL("address",'Version History'!$B$6)} -> '[QuBA-libre.xlsx]Version History'!$B$6
A38: {=IF(INDEX($H:$H,ROW()-1)<>$H38,$E38,"")} | B38: {=IF($K38="","",_xlfn.LET( _xlpm._fullName,IF($L38="",SUBSTITUTE(SUBSTITUTE(INDIRECT($K38),CHAR(10)," ")," "," "),$L38), _xlpm._truncatedName,IF(LEN(_xlpm._fullName)>250,LEFT(_xlpm._fullName,250)&"[…]",_xlpm._fullName), HYPERLINK("#'"&$E38&"'!"&$F38&$G38, _xlpm._truncatedName)))} -> Attack Steps Version History | C38: A version history for the attack step catalog. | E38: =IF($K38="","",_xlfn.LET( _xlpm._in,$K38, _xlpm._start,FIND("]",_xlpm._in)+1, SUBSTITUTE(MID(_xlpm._in,_xlpm._start,FIND("!",_xlpm._in)-_xlpm._start),"'",""))) -> Version History | F38: =IF($K38="","",_xlfn.LET( _xlpm._in,SUBSTITUTE($K38,"$","§",1), _xlpm._start,FIND("§",_xlpm._in)+1, SUBSTITUTE(MID(_xlpm._in,_xlpm._start,FIND("$",_xlpm._in)-_xlpm._start),"'",""))) -> B | G38: =IF($K38="","",RIGHT($K38,LEN($K38)-FIND("$",SUBSTITUTE($K38,"$","§",1)))) -> 11 | H38: {=CreateID($H$35,$E38<>INDEX($E:$E,ROW()-1))} -> 1 | I38: {=INDIRECT($K38)} -> Attack Steps Version History | K38: {=CELL("address",'Version History'!$B$11)} -> '[QuBA-libre.xlsx]Version History'!$B$11
A39: {=IF(INDEX($H:$H,ROW()-1)<>$H39,$E39,"")} | B39: {=IF($K39="","",_xlfn.LET( _xlpm._fullName,IF($L39="",SUBSTITUTE(SUBSTITUTE(INDIRECT($K39),CHAR(10)," ")," "," "),$L39), _xlpm._truncatedName,IF(LEN(_xlpm._fullName)>250,LEFT(_xlpm._fullName,250)&"[…]",_xlpm._fullName), HYPERLINK("#'"&$E39&"'!"&$F39&$G39, _xlpm._truncatedName)))} -> Assumptions Version History | C39: A version history for the assumption catalog. | E39: =IF($K39="","",_xlfn.LET( _xlpm._in,$K39, _xlpm._start,FIND("]",_xlpm._in)+1, SUBSTITUTE(MID(_xlpm._in,_xlpm._start,FIND("!",_xlpm._in)-_xlpm._start),"'",""))) -> Version History | F39: =IF($K39="","",_xlfn.LET( _xlpm._in,SUBSTITUTE($K39,"$","§",1), _xlpm._start,FIND("§",_xlpm._in)+1, SUBSTITUTE(MID(_xlpm._in,_xlpm._start,FIND("$",_xlpm._in)-_xlpm._start),"'",""))) -> B | G39: =IF($K39="","",RIGHT($K39,LEN($K39)-FIND("$",SUBSTITUTE($K39,"$","§",1)))) -> 16 | H39: {=CreateID($H$35,$E39<>INDEX($E:$E,ROW()-1))} -> 1 | I39: {=INDIRECT($K39)} -> Assumptions Version History | K39: {=CELL("address",'Version History'!$B$16)} -> '[QuBA-libre.xlsx]Version History'!$B$16
A40: {=IF(INDEX($H:$H,ROW()-1)<>$H40,$E40,"")} | B40: {=IF($K40="","",_xlfn.LET( _xlpm._fullName,IF($L40="",SUBSTITUTE(SUBSTITUTE(INDIRECT($K40),CHAR(10)," ")," "," "),$L40), _xlpm._truncatedName,IF(LEN(_xlpm._fullName)>250,LEFT(_xlpm._fullName,250)&"[…]",_xlpm._fullName), HYPERLINK("#'"&$E40&"'!"&$F40&$G40, _xlpm._truncatedName)))} -> Countermeasures Version History | C40: A version history for the countermeasure catalog. | E40: =IF($K40="","",_xlfn.LET( _xlpm._in,$K40, _xlpm._start,FIND("]",_xlpm._in)+1, SUBSTITUTE(MID(_xlpm._in,_xlpm._start,FIND("!",_xlpm._in)-_xlpm._start),"'",""))) -> Version History | F40: =IF($K40="","",_xlfn.LET( _xlpm._in,SUBSTITUTE($K40,"$","§",1), _xlpm._start,FIND("§",_xlpm._in)+1, SUBSTITUTE(MID(_xlpm._in,_xlpm._start,FIND("$",_xlpm._in)-_xlpm._start),"'",""))) -> B | G40: =IF($K40="","",RIGHT($K40,LEN($K40)-FIND("$",SUBSTITUTE($K40,"$","§",1)))) -> 21 | H40: {=CreateID($H$35,$E40<>INDEX($E:$E,ROW()-1))} -> 1 | I40: {=INDIRECT($K40)} -> Countermeasures Version History | K40: {=CELL("address",'Version History'!$B$21)} -> '[QuBA-libre.xlsx]Version History'!$B$21
A41: {=IF(INDEX($H:$H,ROW()-1)<>$H41,$E41,"")} -> Definitions | B41: {=IF($K41="","",_xlfn.LET( _xlpm._fullName,IF($L41="",SUBSTITUTE(SUBSTITUTE(INDIRECT($K41),CHAR(10)," ")," "," "),$L41), _xlpm._truncatedName,IF(LEN(_xlpm._fullName)>250,LEFT(_xlpm._fullName,250)&"[…]",_xlpm._fullName), HYPERLINK("#'"&$E41&"'!"&$F41&$G41, _xlpm._truncatedName)))} -> Yes / No | C41: Defines the answers yes and no for the Questionnaire sheet. | E41: =IF($K41="","",_xlfn.LET( _xlpm._in,$K41, _xlpm._start,FIND("]",_xlpm._in)+1, SUBSTITUTE(MID(_xlpm._in,_xlpm._start,FIND("!",_xlpm._in)-_xlpm._start),"'",""))) -> Definitions | F41: =IF($K41="","",_xlfn.LET( _xlpm._in,SUBSTITUTE($K41,"$","§",1), _xlpm._start,FIND("§",_xlpm._in)+1, SUBSTITUTE(MID(_xlpm._in,_xlpm._start,FIND("$",_xlpm._in)-_xlpm._start),"'",""))) -> A | G41: =IF($K41="","",RIGHT($K41,LEN($K41)-FIND("$",SUBSTITUTE($K41,"$","§",1)))) -> 2 | H41: {=CreateID($H$35,$E41<>INDEX($E:$E,ROW()-1))} -> 2 | I41: {=INDIRECT($K41)} -> Yes / No | K41: {=CELL("address",Definitions!$A$2)} -> '[QuBA-libre.xlsx]Definitions'!$A$2
A42: {=IF(INDEX($H:$H,ROW()-1)<>$H42,$E42,"")} | B42: {=IF($K42="","",_xlfn.LET( _xlpm._fullName,IF($L42="",SUBSTITUTE(SUBSTITUTE(INDIRECT($K42),CHAR(10)," ")," "," "),$L42), _xlpm._truncatedName,IF(LEN(_xlpm._fullName)>250,LEFT(_xlpm._fullName,250)&"[…]",_xlpm._fullName), HYPERLINK("#'"&$E42&"'!"&$F42&$G42, _xlpm._truncatedName)))} -> Company Name | C42: Defines the name of the company. | E42: =IF($K42="","",_xlfn.LET( _xlpm._in,$K42, _xlpm._start,FIND("]",_xlpm._in)+1, SUBSTITUTE(MID(_xlpm._in,_xlpm._start,FIND("!",_xlpm._in)-_xlpm._start),"'",""))) -> Definitions | F42: =IF($K42="","",_xlfn.LET( _xlpm._in,SUBSTITUTE($K42,"$","§",1), _xlpm._start,FIND("§",_xlpm._in)+1, SUBSTITUTE(MID(_xlpm._in,_xlpm._start,FIND("$",_xlpm._in)-_xlpm._start),"'",""))) -> C | G42: =IF($K42="","",RIGHT($K42,LEN($K42)-FIND("$",SUBSTITUTE($K42,"$","§",1)))) -> 2 | H42: {=CreateID($H$35,$E42<>INDEX($E:$E,ROW()-1))} -> 2 | I42: {=INDIRECT($K42)} -> Company Name | K42: {=CELL("address",Definitions!$C$2)} -> '[QuBA-libre.xlsx]Definitions'!$C$2
A43: {=IF(INDEX($H:$H,ROW()-1)<>$H43,$E43,"")} | B43: {=IF($K43="","",_xlfn.LET( _xlpm._fullName,IF($L43="",SUBSTITUTE(SUBSTITUTE(INDIRECT($K43),CHAR(10)," ")," "," "),$L43), _xlpm._truncatedName,IF(LEN(_xlpm._fullName)>250,LEFT(_xlpm._fullName,250)&"[…]",_xlpm._fullName), HYPERLINK("#'"&$E43&"'!"&$F43&$G43, _xlpm._truncatedName)))} -> Damage Categories | C43: Defines damage categories to be used in the Questionnaire sheet. | E43: =IF($K43="","",_xlfn.LET( _xlpm._in,$K43, _xlpm._start,FIND("]",_xlpm._in)+1, SUBSTITUTE(MID(_xlpm._in,_xlpm._start,FIND("!",_xlpm._in)-_xlpm._start),"'",""))) -> Definitions | F43: =IF($K43="","",_xlfn.LET( _xlpm._in,SUBSTITUTE($K43,"$","§",1), _xlpm._start,FIND("§",_xlpm._in)+1, SUBSTITUTE(MID(_xlpm._in,_xlpm._start,FIND("$",_xlpm._in)-_xlpm._start),"'",""))) -> E | G43: =IF($K43="","",RIGHT($K43,LEN($K43)-FIND("$",SUBSTITUTE($K43,"$","§",1)))) -> 2 | H43: {=CreateID($H$35,$E43<>INDEX($E:$E,ROW()-1))} -> 2 | I43: {=INDIRECT($K43)} -> Damage Categories | K43: {=CELL("address",Definitions!$E$2)} -> '[QuBA-libre.xlsx]Definitions'!$E$2
A44: {=IF(INDEX($H:$H,ROW()-1)<>$H44,$E44,"")} | B44: {=IF($K44="","",_xlfn.LET( _xlpm._fullName,IF($L44="",SUBSTITUTE(SUBSTITUTE(INDIRECT($K44),CHAR(10)," ")," "," "),$L44), _xlpm._truncatedName,IF(LEN(_xlpm._fullName)>250,LEFT(_xlpm._fullName,250)&"[…]",_xlpm._fullName), HYPERLINK("#'"&$E44&"'!"&$F44&$G44, _xlpm._truncatedName)))} -> Damage Criteria | C44: Defines damage criteria to be used in the Questionnaire sheet. | E44: =IF($K44="","",_xlfn.LET( _xlpm._in,$K44, _xlpm._start,FIND("]",_xlpm._in)+1, SUBSTITUTE(MID(_xlpm._in,_xlpm._start,FIND("!",_xlpm._in)-_xlpm._start),"'",""))) -> Definitions | F44: =IF($K44="","",_xlfn.LET( _xlpm._in,SUBSTITUTE($K44,"$","§",1), _xlpm._start,FIND("§",_xlpm._in)+1, SUBSTITUTE(MID(_xlpm._in,_xlpm._start,FIND("$",_xlpm._in)-_xlpm._start),"'",""))) -> G | G44: =IF($K44="","",RIGHT($K44,LEN($K44)-FIND("$",SUBSTITUTE($K44,"$","§",1)))) -> 2 | H44: {=CreateID($H$35,$E44<>INDEX($E:$E,ROW()-1))} -> 2 | I44: {=INDIRECT($K44)} -> Damage Criteria | K44: {=CELL("address",Definitions!$G$2)} -> '[QuBA-libre.xlsx]Definitions'!$G$2
...

Sheet Answering Guideline
A1: Answering Guideline
A2: Q ID | B2: Question | C2: Answer | D2: Answering Guideline | E2: Follow Up Question | F2: Answer | G2: Answering Guideline | H2: Shadow ID | I2: Sheet Name | J2: Column Letter | K2: Header Row | L2: Sheet # | M2: Column Original Name | N2: Row Color | O2: Q ID2 | Q2: Question Address | R2: Explicit Link Text | S2: Additional information
A3: {=IF($Q3="","",_xlfn.LET( _xlpm._fullName,IF($R3="",SUBSTITUTE(SUBSTITUTE(INDIRECT($Q3),CHAR(10)," ")," "," "),$R3), _xlpm._truncatedName,IF(LEN(_xlpm._fullName)>250,LEFT(_xlpm._fullName,250)&"[…]",_xlpm._fullName), HYPERLINK("#'"&$I3&"'!"&$J3&$K3, _xlpm._truncatedName)))} -> QI1 | B3: {=IF($A3="","",SimpleLookup($A3,Questions!$A:$B))} -> Does the product have / support cameras or other sensors that can potentially identify people? (Regarding "supporting a camera / sensor": only answer with Yes if attaching a camera / sensor is in the intended or foreseeable use of the product.) | C3: Yes | D3: (1) Yes, if information gathered by the device may directly or indirectly make a person identifiable, even if identification is not the intended purpose. Also applies to any biometric or person-related attributes, including but not limited to: * voice or speech characteristics * fingerprints * face or partial face images | E3: {=_xlfn.LET( _xlpm._options,IF($O3="","",SimpleLookup($O3,Questions!$A:$H)), _xlpm._followUpStart,FIND($C3&":",_xlpm._options)+LEN($C3&":"), _xlpm._followUpEnd,FIND(CHAR(10),_xlpm._options&CHAR(10),_xlpm._followUpStart), IF($C3="","",TRIM(MID(_xlpm._options,_xlpm._followUpStart,_xlpm._followUpEnd-_xlpm._followUpStart))))} -> Can you argue that the product cannot identify people in its operational environment? | F3: Yes | G3: (1) Yes, if technical design reliably prevents human capture or recognition. (1a) Physical or mechanical limitations Yes, if the solution is assembled in a way that prevents filming people, for example: * camera permanently directed: - at the floor - into machinery - onto a conveyor belt without human contact - into enclosed compartments * field of view physically blocked - shielding - housing design - mechanical stops * installation height or angle excludes human capture Important: * Must be permanent and not user-adjustable * Must not rely on user configuration | H3: {=CreateID($H$2,$A3<>"")} -> 1 | I3: =IF($Q3="","",_xlfn.LET( _xlpm._in,$Q3, _xlpm._start,FIND("]",_xlpm._in)+1, SUBSTITUTE(MID(_xlpm._in,_xlpm._start,FIND("!",_xlpm._in)-_xlpm._start),"'",""))) -> Questionnaire | J3: =IF($Q3="","",_xlfn.LET( _xlpm._in,SUBSTITUTE($Q3,"$","§",1), _xlpm._start,FIND("§",_xlpm._in)+1, SUBSTITUTE(MID(_xlpm._in,_xlpm._start,FIND("$",_xlpm._in)-_xlpm._start),"'",""))) -> B | K3: =IF($Q3="","",RIGHT($Q3,LEN($Q3)-FIND("$",SUBSTITUTE($Q3,"$","§",1)))) -> 6 | L3: {=CreateID($L$2,$I3<>INDEX($I:$I,ROW()-1))} -> 1 | M3: {=IF($Q3="","",INDIRECT($Q3))} -> QI1 | N3: =IF(MOD($H3,2)=0,"D","L") -> L | O3: =IF($A3="",OFFSET($O3,-1,0),$A3) -> QI1 | Q3: {=CELL("address",Questionnaire!$B$6)} -> '[QuBA-libre.xlsx]Questionnaire'!$B$6
A4: {=IF($Q4="","",_xlfn.LET( _xlpm._fullName,IF($R4="",SUBSTITUTE(SUBSTITUTE(INDIRECT($Q4),CHAR(10)," ")," "," "),$R4), _xlpm._truncatedName,IF(LEN(_xlpm._fullName)>250,LEFT(_xlpm._fullName,250)&"[…]",_xlpm._fullName), HYPERLINK("#'"&$I4&"'!"&$J4&$K4, _xlpm._truncatedName)))} | B4: {=IF($A4="","",SimpleLookup($A4,Questions!$A:$B))} | E4: {=_xlfn.LET( _xlpm._options,IF($O4="","",SimpleLookup($O4,Questions!$A:$H)), _xlpm._followUpStart,FIND($C4&":",_xlpm._options)+LEN($C4&":"), _xlpm._followUpEnd,FIND(CHAR(10),_xlpm._options&CHAR(10),_xlpm._followUpStart), IF($C4="","",TRIM(MID(_xlpm._options,_xlpm._followUpStart,_xlpm._followUpEnd-_xlpm._followUpStart))))} | G4: (1b) Sensor technology inherently prevents identification Yes, if the device uses sensors where human identification is technically impossible, such as: * low-resolution LiDAR without reflectivity mapping * binary presence sensors * ultrasonic distance sensors * infrared break beams * coarse occupancy detection Not valid if: * reflectivity data is recorded * high-resolution depth cameras are used | H4: {=CreateID($H$2,$A4<>"")} -> 1 | I4: =IF($Q4="","",_xlfn.LET( _xlpm._in,$Q4, _xlpm._start,FIND("]",_xlpm._in)+1, SUBSTITUTE(MID(_xlpm._in,_xlpm._start,FIND("!",_xlpm._in)-_xlpm._start),"'",""))) | J4: =IF($Q4="","",_xlfn.LET( _xlpm._in,SUBSTITUTE($Q4,"$","§",1), _xlpm._start,FIND("§",_xlpm._in)+1, SUBSTITUTE(MID(_xlpm._in,_xlpm._start,FIND("$",_xlpm._in)-_xlpm._start),"'",""))) | K4: =IF($Q4="","",RIGHT($Q4,LEN($Q4)-FIND("$",SUBSTITUTE($Q4,"$","§",1)))) | L4: {=CreateID($L$2,$I4<>INDEX($I:$I,ROW()-1))} -> 2 | M4: {=IF($Q4="","",INDIRECT($Q4))} | N4: =IF(MOD($H4,2)=0,"D","L") -> L | O4: =IF($A4="",OFFSET($O4,-1,0),$A4) -> QI1
A5: {=IF($Q5="","",_xlfn.LET( _xlpm._fullName,IF($R5="",SUBSTITUTE(SUBSTITUTE(INDIRECT($Q5),CHAR(10)," ")," "," "),$R5), _xlpm._truncatedName,IF(LEN(_xlpm._fullName)>250,LEFT(_xlpm._fullName,250)&"[…]",_xlpm._fullName), HYPERLINK("#'"&$I5&"'!"&$J5&$K5, _xlpm._truncatedName)))} | B5: {=IF($A5="","",SimpleLookup($A5,Questions!$A:$B))} | E5: {=_xlfn.LET( _xlpm._options,IF($O5="","",SimpleLookup($O5,Questions!$A:$H)), _xlpm._followUpStart,FIND($C5&":",_xlpm._options)+LEN($C5&":"), _xlpm._followUpEnd,FIND(CHAR(10),_xlpm._options&CHAR(10),_xlpm._followUpStart), IF($C5="","",TRIM(MID(_xlpm._options,_xlpm._followUpStart,_xlpm._followUpEnd-_xlpm._followUpStart))))} | G5: (1c) Human-free operating environments Yes, if the device operates exclusively in environments without humans, such as: * sealed industrial cells * fenced robotic zones with interlocks * restricted access technical rooms * automated warehouses without personnel Conditions: * access control must exist * normal operation must exclude humans * occasional maintenance does not invalidate this Not valid if: * device can be redeployed elsewhere * environment is only "normally" empty * device is customer-installable | H5: {=CreateID($H$2,$A5<>"")} -> 1 | I5: =IF($Q5="","",_xlfn.LET( _xlpm._in,$Q5, _xlpm._start,FIND("]",_xlpm._in)+1, SUBSTITUTE(MID(_xlpm._in,_xlpm._start,FIND("!",_xlpm._in)-_xlpm._start),"'",""))) | J5: =IF($Q5="","",_xlfn.LET( _xlpm._in,SUBSTITUTE($Q5,"$","§",1), _xlpm._start,FIND("§",_xlpm._in)+1, SUBSTITUTE(MID(_xlpm._in,_xlpm._start,FIND("$",_xlpm._in)-_xlpm._start),"'",""))) | K5: =IF($Q5="","",RIGHT($Q5,LEN($Q5)-FIND("$",SUBSTITUTE($Q5,"$","§",1)))) | L5: {=CreateID($L$2,$I5<>INDEX($I:$I,ROW()-1))} -> 2 | M5: {=IF($Q5="","",INDIRECT($Q5))} | N5: =IF(MOD($H5,2)=0,"D","L") -> L | O5: =IF($A5="",OFFSET($O5,-1,0),$A5) -> QI1
A6: {=IF($Q6="","",_xlfn.LET( _xlpm._fullName,IF($R6="",SUBSTITUTE(SUBSTITUTE(INDIRECT($Q6),CHAR(10)," ")," "," "),$R6), _xlpm._truncatedName,IF(LEN(_xlpm._fullName)>250,LEFT(_xlpm._fullName,250)&"[…]",_xlpm._fullName), HYPERLINK("#'"&$I6&"'!"&$J6&$K6, _xlpm._truncatedName)))} | B6: {=IF($A6="","",SimpleLookup($A6,Questions!$A:$B))} | E6: {=_xlfn.LET( _xlpm._options,IF($O6="","",SimpleLookup($O6,Questions!$A:$H)), _xlpm._followUpStart,FIND($C6&":",_xlpm._options)+LEN($C6&":"), _xlpm._followUpEnd,FIND(CHAR(10),_xlpm._options&CHAR(10),_xlpm._followUpStart), IF($C6="","",TRIM(MID(_xlpm._options,_xlpm._followUpStart,_xlpm._followUpEnd-_xlpm._followUpStart))))} | F6: No | G6: (2) No — cannot argue that the solution avoids filming or detecting people (2a) Field of view includes humans No, if the device is assembled or positioned in a way that allows people in its field of view. Examples: * cameras facing corridors * cameras facing workstations * cameras in public or semi-public areas * adjustable camera mounts (2b) Human-related features exist No, if the system includes functions such as: * facial recognition * person detection * people counting * gesture recognition * crowd monitoring Even if: * features are disabled by default * features are optional (2c) Mobile or autonomous devices No, if the device is mobile and navigates through mixed-use environments, such as: * offices * retail spaces * hospitals * airports * logistics areas with staff present Unless: * active technical measures prevent capture of people * or sensors cannot detect humans at all | H6: {=CreateID($H$2,$A6<>"")} -> 1 | I6: =IF($Q6="","",_xlfn.LET( _xlpm._in,$Q6, _xlpm._start,FIND("]",_xlpm._in)+1, SUBSTITUTE(MID(_xlpm._in,_xlpm._start,FIND("!",_xlpm._in)-_xlpm._start),"'",""))) | J6: =IF($Q6="","",_xlfn.LET( _xlpm._in,SUBSTITUTE($Q6,"$","§",1), _xlpm._start,FIND("§",_xlpm._in)+1, SUBSTITUTE(MID(_xlpm._in,_xlpm._start,FIND("$",_xlpm._in)-_xlpm._start),"'",""))) | K6: =IF($Q6="","",RIGHT($Q6,LEN($Q6)-FIND("$",SUBSTITUTE($Q6,"$","§",1)))) | L6: {=CreateID($L$2,$I6<>INDEX($I:$I,ROW()-1))} -> 2 | M6: {=IF($Q6="","",INDIRECT($Q6))} | N6: =IF(MOD($H6,2)=0,"D","L") -> L | O6: =IF($A6="",OFFSET($O6,-1,0),$A6) -> QI1
A7: {=IF($Q7="","",_xlfn.LET( _xlpm._fullName,IF($R7="",SUBSTITUTE(SUBSTITUTE(INDIRECT($Q7),CHAR(10)," ")," "," "),$R7), _xlpm._truncatedName,IF(LEN(_xlpm._fullName)>250,LEFT(_xlpm._fullName,250)&"[…]",_xlpm._fullName), HYPERLINK("#'"&$I7&"'!"&$J7&$K7, _xlpm._truncatedName)))} | B7: {=IF($A7="","",SimpleLookup($A7,Questions!$A:$B))} | C7: No | D7: (2) No, only if it is technically impossible to identify a person based on the collected data. Applies if: * sensors measure only environmental data (e.g. temperature, humidity, pressure) * sensors measure only mechanical states (e.g. motor current, vibration) * resolution and sensor design make identification impossible * sensor output is strictly numerical without human-related attributes | E7: {=_xlfn.LET( _xlpm._options,IF($O7="","",SimpleLookup($O7,Questions!$A:$H)), _xlpm._followUpStart,FIND($C7&":",_xlpm._options)+LEN($C7&":"), _xlpm._followUpEnd,FIND(CHAR(10),_xlpm._options&CHAR(10),_xlpm._followUpStart), IF($C7="","",TRIM(MID(_xlpm._options,_xlpm._followUpStart,_xlpm._followUpEnd-_xlpm._followUpStart))))} | H7: {=CreateID($H$2,$A7<>"")} -> 1 | I7: =IF($Q7="","",_xlfn.LET( _xlpm._in,$Q7, _xlpm._start,FIND("]",_xlpm._in)+1, SUBSTITUTE(MID(_xlpm._in,_xlpm._start,FIND("!",_xlpm._in)-_xlpm._start),"'",""))) | J7: =IF($Q7="","",_xlfn.LET( _xlpm._in,SUBSTITUTE($Q7,"$","§",1), _xlpm._start,FIND("§",_xlpm._in)+1, SUBSTITUTE(MID(_xlpm._in,_xlpm._start,FIND("$",_xlpm._in)-_xlpm._start),"'",""))) | K7: =IF($Q7="","",RIGHT($Q7,LEN($Q7)-FIND("$",SUBSTITUTE($Q7,"$","§",1)))) | L7: {=CreateID($L$2,$I7<>INDEX($I:$I,ROW()-1))} -> 2 | M7: {=IF($Q7="","",INDIRECT($Q7))} | N7: =IF(MOD($H7,2)=0,"D","L") -> L | O7: =IF($A7="",OFFSET($O7,-1,0),$A7) -> QI1
A8: {=IF($Q8="","",_xlfn.LET( _xlpm._fullName,IF($R8="",SUBSTITUTE(SUBSTITUTE(INDIRECT($Q8),CHAR(10)," ")," "," "),$R8), _xlpm._truncatedName,IF(LEN(_xlpm._fullName)>250,LEFT(_xlpm._fullName,250)&"[…]",_xlpm._fullName), HYPERLINK("#'"&$I8&"'!"&$J8&$K8, _xlpm._truncatedName)))} -> QI2 | B8: {=IF($A8="","",SimpleLookup($A8,Questions!$A:$B))} -> Does the product process personal data? Examples: address labels | C8: Yes | D8: (1) Yes, if the solution collects, stores, transmits, or processes information relating to an identifiable person, directly or indirectly. Examples: * User accounts can be created or modified * People appear in captured image or sensor data * Processing of licence plates from vehicles * Reading address labels or shipping data * Object-related data that can be linked to a person (e.g. assigned workstations, personalized tools, operator IDs) Also Yes if: * data is transmitted to external systems * logs contain user names or IDs * remote access identifies operators | E8: {=_xlfn.LET( _xlpm._options,IF($O8="","",SimpleLookup($O8,Questions!$A:$H)), _xlpm._followUpStart,FIND($C8&":",_xlpm._options)+LEN($C8&":"), _xlpm._followUpEnd,FIND(CHAR(10),_xlpm._options&CHAR(10),_xlpm._followUpStart), IF($C8="","",TRIM(MID(_xlpm._options,_xlpm._followUpStart,_xlpm._followUpEnd-_xlpm._followUpStart))))} -> What is the criticality of the processed data? | G8: Classify the worst credible impact on the affected person if the data is disclosed or misused. | H8: {=CreateID($H$2,$A8<>"")} -> 2 | I8: =IF($Q8="","",_xlfn.LET( _xlpm._in,$Q8, _xlpm._start,FIND("]",_xlpm._in)+1, SUBSTITUTE(MID(_xlpm._in,_xlpm._start,FIND("!",_xlpm._in)-_xlpm._start),"'",""))) -> Questionnaire | J8: =IF($Q8="","",_xlfn.LET( _xlpm._in,SUBSTITUTE($Q8,"$","§",1), _xlpm._start,FIND("§",_xlpm._in)+1, SUBSTITUTE(MID(_xlpm._in,_xlpm._start,FIND("$",_xlpm._in)-_xlpm._start),"'",""))) -> B | K8: =IF($Q8="","",RIGHT($Q8,LEN($Q8)-FIND("$",SUBSTITUTE($Q8,"$","§",1)))) -> 7 | L8: {=CreateID($L$2,$I8<>INDEX($I:$I,ROW()-1))} -> 3 | M8: {=IF($Q8="","",INDIRECT($Q8))} -> QI2 | N8: =IF(MOD($H8,2)=0,"D","L") -> D | O8: =IF($A8="",OFFSET($O8,-1,0),$A8) -> QI2 | Q8: {=CELL("address",Questionnaire!$B$7)} -> '[QuBA-libre.xlsx]Questionnaire'!$B$7
A9: {=IF($Q9="","",_xlfn.LET( _xlpm._fullName,IF($R9="",SUBSTITUTE(SUBSTITUTE(INDIRECT($Q9),CHAR(10)," ")," "," "),$R9), _xlpm._truncatedName,IF(LEN(_xlpm._fullName)>250,LEFT(_xlpm._fullName,250)&"[…]",_xlpm._fullName), HYPERLINK("#'"&$I9&"'!"&$J9&$K9, _xlpm._truncatedName)))} | B9: {=IF($A9="","",SimpleLookup($A9,Questions!$A:$B))} | E9: {=_xlfn.LET( _xlpm._options,IF($O9="","",SimpleLookup($O9,Questions!$A:$H)), _xlpm._followUpStart,FIND($C9&":",_xlpm._options)+LEN($C9&":"), _xlpm._followUpEnd,FIND(CHAR(10),_xlpm._options&CHAR(10),_xlpm._followUpStart), IF($C9="","",TRIM(MID(_xlpm._options,_xlpm._followUpStart,_xlpm._followUpEnd-_xlpm._followUpStart))))} | F9: =Definitions!$H$5 -> Personal data (significant) | G9: The affected person may experience limited negative effects on social or economic circumstances. Damage level Low Examples: * name without additional context * basic contact data * non-sensitive shipment data * licence plates without tracking history | H9: {=CreateID($H$2,$A9<>"")} -> 2 | I9: =IF($Q9="","",_xlfn.LET( _xlpm._in,$Q9, _xlpm._start,FIND("]",_xlpm._in)+1, SUBSTITUTE(MID(_xlpm._in,_xlpm._start,FIND("!",_xlpm._in)-_xlpm._start),"'",""))) | J9: =IF($Q9="","",_xlfn.LET( _xlpm._in,SUBSTITUTE($Q9,"$","§",1), _xlpm._start,FIND("§",_xlpm._in)+1, SUBSTITUTE(MID(_xlpm._in,_xlpm._start,FIND("$",_xlpm._in)-_xlpm._start),"'",""))) | K9: =IF($Q9="","",RIGHT($Q9,LEN($Q9)-FIND("$",SUBSTITUTE($Q9,"$","§",1)))) | L9: {=CreateID($L$2,$I9<>INDEX($I:$I,ROW()-1))} -> 4 | M9: {=IF($Q9="","",INDIRECT($Q9))} | N9: =IF(MOD($H9,2)=0,"D","L") -> D | O9: =IF($A9="",OFFSET($O9,-1,0),$A9) -> QI2
A10: {=IF($Q10="","",_xlfn.LET( _xlpm._fullName,IF($R10="",SUBSTITUTE(SUBSTITUTE(INDIRECT($Q10),CHAR(10)," ")," "," "),$R10), _xlpm._truncatedName,IF(LEN(_xlpm._fullName)>250,LEFT(_xlpm._fullName,250)&"[…]",_xlpm._fullName), HYPERLINK("#'"&$I10&"'!"&$J10&$K10, _xlpm._truncatedName)))} | B10: {=IF($A10="","",SimpleLookup($A10,Questions!$A:$B))} | E10: {=_xlfn.LET( _xlpm._options,IF($O10="","",SimpleLookup($O10,Questions!$A:$H)), _xlpm._followUpStart,FIND($C10&":",_xlpm._options)+LEN($C10&":"), _xlpm._followUpEnd,FIND(CHAR(10),_xlpm._options&CHAR(10),_xlpm._followUpStart), IF($C10="","",TRIM(MID(_xlpm._options,_xlpm._followUpStart,_xlpm._followUpEnd-_xlpm._followUpStart))))} | F10: =Definitions!$H$6 -> Personal data (ruinous) | G10: The affected person may be significantly impaired in social or economic circumstances. Damage level High Examples: * tracking data * full name, adress and personal data * detailed employment-related data * linked datasets enabling profiling | H10: {=CreateID($H$2,$A10<>"")} -> 2 | I10: =IF($Q10="","",_xlfn.LET( _xlpm._in,$Q10, _xlpm._start,FIND("]",_xlpm._in)+1, SUBSTITUTE(MID(_xlpm._in,_xlpm._start,FIND("!",_xlpm._in)-_xlpm._start),"'",""))) | J10: =IF($Q10="","",_xlfn.LET( _xlpm._in,SUBSTITUTE($Q10,"$","§",1), _xlpm._start,FIND("§",_xlpm._in)+1, SUBSTITUTE(MID(_xlpm._in,_xlpm._start,FIND("$",_xlpm._in)-_xlpm._start),"'",""))) | K10: =IF($Q10="","",RIGHT($Q10,LEN($Q10)-FIND("$",SUBSTITUTE($Q10,"$","§",1)))) | L10: {=CreateID($L$2,$I10<>INDEX($I:$I,ROW()-1))} -> 4 | M10: {=IF($Q10="","",INDIRECT($Q10))} | N10: =IF(MOD($H10,2)=0,"D","L") -> D | O10: =IF($A10="",OFFSET($O10,-1,0),$A10) -> QI2
A11: {=IF($Q11="","",_xlfn.LET( _xlpm._fullName,IF($R11="",SUBSTITUTE(SUBSTITUTE(INDIRECT($Q11),CHAR(10)," ")," "," "),$R11), _xlpm._truncatedName,IF(LEN(_xlpm._fullName)>250,LEFT(_xlpm._fullName,250)&"[…]",_xlpm._fullName), HYPERLINK("#'"&$I11&"'!"&$J11&$K11, _xlpm._truncatedName)))} | B11: {=IF($A11="","",SimpleLookup($A11,Questions!$A:$B))} | E11: {=_xlfn.LET( _xlpm._options,IF($O11="","",SimpleLookup($O11,Questions!$A:$H)), _xlpm._followUpStart,FIND($C11&":",_xlpm._options)+LEN($C11&":"), _xlpm._followUpEnd,FIND(CHAR(10),_xlpm._options&CHAR(10),_xlpm._followUpStart), IF($C11="","",TRIM(MID(_xlpm._options,_xlpm._followUpStart,_xlpm._followUpEnd-_xlpm._followUpStart))))} | F11: =Definitions!$H$7 -> IP (slightly innovative) | G11: The affected person may be severely or irreversibly harmed, or personal freedom may be threatened. Damage level Critical Examples: * biometric identifiers * access credentials * security-related personal data * comprehensive personal profiles * sexual identity * health information | H11: {=CreateID($H$2,$A11<>"")} -> 2 | I11: =IF($Q11="","",_xlfn.LET( _xlpm._in,$Q11, _xlpm._start,FIND("]",_xlpm._in)+1, SUBSTITUTE(MID(_xlpm._in,_xlpm._start,FIND("!",_xlpm._in)-_xlpm._start),"'",""))) | J11: =IF($Q11="","",_xlfn.LET( _xlpm._in,SUBSTITUTE($Q11,"$","§",1), _xlpm._start,FIND("§",_xlpm._in)+1, SUBSTITUTE(MID(_xlpm._in,_xlpm._start,FIND("$",_xlpm._in)-_xlpm._start),"'",""))) | K11: =IF($Q11="","",RIGHT($Q11,LEN($Q11)-FIND("$",SUBSTITUTE($Q11,"$","§",1)))) | L11: {=CreateID($L$2,$I11<>INDEX($I:$I,ROW()-1))} -> 4 | M11: {=IF($Q11="","",INDIRECT($Q11))} | N11: =IF(MOD($H11,2)=0,"D","L") -> D | O11: =IF($A11="",OFFSET($O11,-1,0),$A11) -> QI2
A12: {=IF($Q12="","",_xlfn.LET( _xlpm._fullName,IF($R12="",SUBSTITUTE(SUBSTITUTE(INDIRECT($Q12),CHAR(10)," ")," "," "),$R12), _xlpm._truncatedName,IF(LEN(_xlpm._fullName)>250,LEFT(_xlpm._fullName,250)&"[…]",_xlpm._fullName), HYPERLINK("#'"&$I12&"'!"&$J12&$K12, _xlpm._truncatedName)))} | B12: {=IF($A12="","",SimpleLookup($A12,Questions!$A:$B))} | C12: No | D12: (2) No, if the solution processes only technical or anonymous data, for example: * distances or object dimensions * barcode numbers without personal reference * machine states or diagnostics * anonymous object tracking (2*) Unclear If there is any doubt when selecting No → consult the Data Protection Office. | E12: {=_xlfn.LET( _xlpm._options,IF($O12="","",SimpleLookup($O12,Questions!$A:$H)), _xlpm._followUpStart,FIND($C12&":",_xlpm._options)+LEN($C12&":"), _xlpm._followUpEnd,FIND(CHAR(10),_xlpm._options&CHAR(10),_xlpm._followUpStart), IF($C12="","",TRIM(MID(_xlpm._options,_xlpm._followUpStart,_xlpm._followUpEnd-_xlpm._followUpStart))))} | H12: {=CreateID($H$2,$A12<>"")} -> 2 | I12: =IF($Q12="","",_xlfn.LET( _xlpm._in,$Q12, _xlpm._start,FIND("]",_xlpm._in)+1, SUBSTITUTE(MID(_xlpm._in,_xlpm._start,FIND("!",_xlpm._in)-_xlpm._start),"'",""))) | J12: =IF($Q12="","",_xlfn.LET( _xlpm._in,SUBSTITUTE($Q12,"$","§",1), _xlpm._start,FIND("§",_xlpm._in)+1, SUBSTITUTE(MID(_xlpm._in,_xlpm._start,FIND("$",_xlpm._in)-_xlpm._start),"'",""))) | K12: =IF($Q12="","",RIGHT($Q12,LEN($Q12)-FIND("$",SUBSTITUTE($Q12,"$","§",1)))) | L12: {=CreateID($L$2,$I12<>INDEX($I:$I,ROW()-1))} -> 4 | M12: {=IF($Q12="","",INDIRECT($Q12))} | N12: =IF(MOD($H12,2)=0,"D","L") -> D | O12: =IF($A12="",OFFSET($O12,-1,0),$A12) -> QI2
A13: {=IF($Q13="","",_xlfn.LET( _xlpm._fullName,IF($R13="",SUBSTITUTE(SUBSTITUTE(INDIRECT($Q13),CHAR(10)," ")," "," "),$R13), _xlpm._truncatedName,IF(LEN(_xlpm._fullName)>250,LEFT(_xlpm._fullName,250)&"[…]",_xlpm._fullName), HYPERLINK("#'"&$I13&"'!"&$J13&$K13, _xlpm._truncatedName)))} -> QI3 | B13: {=IF($A13="","",SimpleLookup($A13,Questions!$A:$B))} -> Does the product contain << OEM Name >> or customer intellectual property? Note: Only IP which is part of / accessible by the firmware / software in the product is in scope of this question. Gaining access to optical and mechanical IP are not covered by this question (and the cybersecurity risk analysis) | C13: Yes | D13: (1) Yes, if the solution contains non-public software or firmware intellectual property. | E13: {=_xlfn.LET( _xlpm._options,IF($O13="","",SimpleLookup($O13,Questions!$A:$H)), _xlpm._followUpStart,FIND($C13&":",_xlpm._options)+LEN($C13&":"), _xlpm._followUpEnd,FIND(CHAR(10),_xlpm._options&CHAR(10),_xlpm._followUpStart), IF($C13="","",TRIM(MID(_xlpm._options,_xlpm._followUpStart,_xlpm._followUpEnd-_xlpm._followUpStart))))} -> What is the criticality of the intellectual property? | F13: =Definitions!$H$8 -> IP (moderately innovative) | G13: Loss of the general idea how solution works or low impact on markets (little innovation / very small market) | H13: {=CreateID($H$2,$A13<>"")} -> 3 | I13: =IF($Q13="","",_xlfn.LET( _xlpm._in,$Q13, _xlpm._start,FIND("]",_xlpm._in)+1, SUBSTITUTE(MID(_xlpm._in,_xlpm._start,FIND("!",_xlpm._in)-_xlpm._start),"'",""))) -> Questionnaire | J13: =IF($Q13="","",_xlfn.LET( _xlpm._in,SUBSTITUTE($Q13,"$","§",1), _xlpm._start,FIND("§",_xlpm._in)+1, SUBSTITUTE(MID(_xlpm._in,_xlpm._start,FIND("$",_xlpm._in)-_xlpm._start),"'",""))) -> B | K13: =IF($Q13="","",RIGHT($Q13,LEN($Q13)-FIND("$",SUBSTITUTE($Q13,"$","§",1)))) -> 9 | L13: {=CreateID($L$2,$I13<>INDEX($I:$I,ROW()-1))} -> 5 | M13: {=IF($Q13="","",INDIRECT($Q13))} -> QI3 | N13: =IF(MOD($H13,2)=0,"D","L") -> L | O13: =IF($A13="",OFFSET($O13,-1,0),$A13) -> QI3 | Q13: {=CELL("address",Questionnaire!$B$9)} -> '[QuBA-libre.xlsx]Questionnaire'!$B$9
A14: {=IF($Q14="","",_xlfn.LET( _xlpm._fullName,IF($R14="",SUBSTITUTE(SUBSTITUTE(INDIRECT($Q14),CHAR(10)," ")," "," "),$R14), _xlpm._truncatedName,IF(LEN(_xlpm._fullName)>250,LEFT(_xlpm._fullName,250)&"[…]",_xlpm._fullName), HYPERLINK("#'"&$I14&"'!"&$J14&$K14, _xlpm._truncatedName)))} | B14: {=IF($A14="","",SimpleLookup($A14,Questions!$A:$B))} | E14: {=_xlfn.LET( _xlpm._options,IF($O14="","",SimpleLookup($O14,Questions!$A:$H)), _xlpm._followUpStart,FIND($C14&":",_xlpm._options)+LEN($C14&":"), _xlpm._followUpEnd,FIND(CHAR(10),_xlpm._options&CHAR(10),_xlpm._followUpStart), IF($C14="","",TRIM(MID(_xlpm._options,_xlpm._followUpStart,_xlpm._followUpEnd-_xlpm._followUpStart))))} | F14: =Definitions!$H$9 -> IP (highly innovative) | G14: Relevant aspects of system is comprehensible or moderate impact on markets (some innovation in the solution / medium size market) | H14: {=CreateID($H$2,$A14<>"")} -> 3 | I14: =IF($Q14="","",_xlfn.LET( _xlpm._in,$Q14, _xlpm._start,FIND("]",_xlpm._in)+1, SUBSTITUTE(MID(_xlpm._in,_xlpm._start,FIND("!",_xlpm._in)-_xlpm._start),"'",""))) | J14: =IF($Q14="","",_xlfn.LET( _xlpm._in,SUBSTITUTE($Q14,"$","§",1), _xlpm._start,FIND("§",_xlpm._in)+1, SUBSTITUTE(MID(_xlpm._in,_xlpm._start,FIND("$",_xlpm._in)-_xlpm._start),"'",""))) | K14: =IF($Q14="","",RIGHT($Q14,LEN($Q14)-FIND("$",SUBSTITUTE($Q14,"$","§",1)))) | L14: {=CreateID($L$2,$I14<>INDEX($I:$I,ROW()-1))} -> 6 | M14: {=IF($Q14="","",INDIRECT($Q14))} | N14: =IF(MOD($H14,2)=0,"D","L") -> L | O14: =IF($A14="",OFFSET($O14,-1,0),$A14) -> QI3
A15: {=IF($Q15="","",_xlfn.LET( _xlpm._fullName,IF($R15="",SUBSTITUTE(SUBSTITUTE(INDIRECT($Q15),CHAR(10)," ")," "," "),$R15), _xlpm._truncatedName,IF(LEN(_xlpm._fullName)>250,LEFT(_xlpm._fullName,250)&"[…]",_xlpm._fullName), HYPERLINK("#'"&$I15&"'!"&$J15&$K15, _xlpm._truncatedName)))} | B15: {=IF($A15="","",SimpleLookup($A15,Questions!$A:$B))} | E15: {=_xlfn.LET( _xlpm._options,IF($O15="","",SimpleLookup($O15,Questions!$A:$H)), _xlpm._followUpStart,FIND($C15&":",_xlpm._options)+LEN($C15&":"), _xlpm._followUpEnd,FIND(CHAR(10),_xlpm._options&CHAR(10),_xlpm._followUpStart), IF($C15="","",TRIM(MID(_xlpm._options,_xlpm._followUpStart,_xlpm._followUpEnd-_xlpm._followUpStart))))} | F15: =Definitions!$H$10 -> Low financial damage | G15: Can be copied / technology available or high impact on markets (highly innovative solution / high-volume market) | H15: {=CreateID($H$2,$A15<>"")} -> 3 | I15: =IF($Q15="","",_xlfn.LET( _xlpm._in,$Q15, _xlpm._start,FIND("]",_xlpm._in)+1, SUBSTITUTE(MID(_xlpm._in,_xlpm._start,FIND("!",_xlpm._in)-_xlpm._start),"'",""))) | J15: =IF($Q15="","",_xlfn.LET( _xlpm._in,SUBSTITUTE($Q15,"$","§",1), _xlpm._start,FIND("§",_xlpm._in)+1, SUBSTITUTE(MID(_xlpm._in,_xlpm._start,FIND("$",_xlpm._in)-_xlpm._start),"'",""))) | K15: =IF($Q15="","",RIGHT($Q15,LEN($Q15)-FIND("$",SUBSTITUTE($Q15,"$","§",1)))) | L15: {=CreateID($L$2,$I15<>INDEX($I:$I,ROW()-1))} -> 6 | M15: {=IF($Q15="","",INDIRECT($Q15))} | N15: =IF(MOD($H15,2)=0,"D","L") -> L | O15: =IF($A15="",OFFSET($O15,-1,0),$A15) -> QI3
A16: {=IF($Q16="","",_xlfn.LET( _xlpm._fullName,IF($R16="",SUBSTITUTE(SUBSTITUTE(INDIRECT($Q16),CHAR(10)," ")," "," "),$R16), _xlpm._truncatedName,IF(LEN(_xlpm._fullName)>250,LEFT(_xlpm._fullName,250)&"[…]",_xlpm._fullName), HYPERLINK("#'"&$I16&"'!"&$J16&$K16, _xlpm._truncatedName)))} | B16: {=IF($A16="","",SimpleLookup($A16,Questions!$A:$B))} | C16: No | D16: (2) No, if the solution contains only public or standard software components | E16: {=_xlfn.LET( _xlpm._options,IF($O16="","",SimpleLookup($O16,Questions!$A:$H)), _xlpm._followUpStart,FIND($C16&":",_xlpm._options)+LEN($C16&":"), _xlpm._followUpEnd,FIND(CHAR(10),_xlpm._options&CHAR(10),_xlpm._followUpStart), IF($C16="","",TRIM(MID(_xlpm._options,_xlpm._followUpStart,_xlpm._followUpEnd-_xlpm._followUpStart))))} | H16: {=CreateID($H$2,$A16<>"")} -> 3 | I16: =IF($Q16="","",_xlfn.LET( _xlpm._in,$Q16, _xlpm._start,FIND("]",_xlpm._in)+1, SUBSTITUTE(MID(_xlpm._in,_xlpm._start,FIND("!",_xlpm._in)-_xlpm._start),"'",""))) | J16: =IF($Q16="","",_xlfn.LET( _xlpm._in,SUBSTITUTE($Q16,"$","§",1), _xlpm._start,FIND("§",_xlpm._in)+1, SUBSTITUTE(MID(_xlpm._in,_xlpm._start,FIND("$",_xlpm._in)-_xlpm._start),"'",""))) | K16: =IF($Q16="","",RIGHT($Q16,LEN($Q16)-FIND("$",SUBSTITUTE($Q16,"$","§",1)))) | L16: {=CreateID($L$2,$I16<>INDEX($I:$I,ROW()-1))} -> 6 | M16: {=IF($Q16="","",INDIRECT($Q16))} | N16: =IF(MOD($H16,2)=0,"D","L") -> L | O16: =IF($A16="",OFFSET($O16,-1,0),$A16) -> QI3
A17: {=IF($Q17="","",_xlfn.LET( _xlpm._fullName,IF($R17="",SUBSTITUTE(SUBSTITUTE(INDIRECT($Q17),CHAR(10)," ")," "," "),$R17), _xlpm._truncatedName,IF(LEN(_xlpm._fullName)>250,LEFT(_xlpm._fullName,250)&"[…]",_xlpm._fullName), HYPERLINK("#'"&$I17&"'!"&$J17&$K17, _xlpm._truncatedName)))} -> QI4 | B17: {=IF($A17="","",SimpleLookup($A17,Questions!$A:$B))} -> Is << OEM Name >> (typically) obliged to keep the processed / stored data (including third-party IP) confidential by contract or law? (Note that this concerns individual obligations, not the standard product warranty). | C17: Yes | D17: (1) Yes, if it is reasonable that customer may require such an obligation (1*)The PM should be able to answer this question. | E17: {=_xlfn.LET( _xlpm._options,IF($O17="","",SimpleLookup($O17,Questions!$A:$H)), _xlpm._followUpStart,FIND($C17&":",_xlpm._options)+LEN($C17&":"), _xlpm._followUpEnd,FIND(CHAR(10),_xlpm._options&CHAR(10),_xlpm._followUpStart), IF($C17="","",TRIM(MID(_xlpm._options,_xlpm._followUpStart,_xlpm._followUpEnd-_xlpm._followUpStart))))} -> What is the typical / expected value of direct loss, fines for infringements of laws, or violations of contracts? | G17: ="Classify the potential direct financial damage to "&Definitions!$C$4&" caused by an incident" -> Classify the potential direct financial damage to << OEM Name >> caused by an incident | H17: {=CreateID($H$2,$A17<>"")} -> 4 | I17: =IF($Q17="","",_xlfn.LET( _xlpm._in,$Q17, _xlpm._start,FIND("]",_xlpm._in)+1, SUBSTITUTE(MID(_xlpm._in,_xlpm._start,FIND("!",_xlpm._in)-_xlpm._start),"'",""))) -> Questionnaire | J17: =IF($Q17="","",_xlfn.LET( _xlpm._in,SUBSTITUTE($Q17,"$","§",1), _xlpm._start,FIND("§",_xlpm._in)+1, SUBSTITUTE(MID(_xlpm._in,_xlpm._start,FIND("$",_xlpm._in)-_xlpm._start),"'",""))) -> B | K17: =IF($Q17="","",RIGHT($Q17,LEN($Q17)-FIND("$",SUBSTITUTE($Q17,"$","§",1)))) -> 11 | L17: {=CreateID($L$2,$I17<>INDEX($I:$I,ROW()-1))} -> 7 | M17: {=IF($Q17="","",INDIRECT($Q17))} -> QI4 | N17: =IF(MOD($H17,2)=0,"D","L") -> D | O17: =IF($A17="",OFFSET($O17,-1,0),$A17) -> QI4 | Q17: {=CELL("address",Questionnaire!$B$11)} -> '[QuBA-libre.xlsx]Questionnaire'!$B$11
A18: {=IF($Q18="","",_xlfn.LET( _xlpm._fullName,IF($R18="",SUBSTITUTE(SUBSTITUTE(INDIRECT($Q18),CHAR(10)," ")," "," "),$R18), _xlpm._truncatedName,IF(LEN(_xlpm._fullName)>250,LEFT(_xlpm._fullName,250)&"[…]",_xlpm._fullName), HYPERLINK("#'"&$I18&"'!"&$J18&$K18, _xlpm._truncatedName)))} | B18: {=IF($A18="","",SimpleLookup($A18,Questions!$A:$B))} | E18: {=_xlfn.LET( _xlpm._options,IF($O18="","",SimpleLookup($O18,Questions!$A:$H)), _xlpm._followUpStart,FIND($C18&":",_xlpm._options)+LEN($C18&":"), _xlpm._followUpEnd,FIND(CHAR(10),_xlpm._options&CHAR(10),_xlpm._followUpStart), IF($C18="","",TRIM(MID(_xlpm._options,_xlpm._followUpStart,_xlpm._followUpEnd-_xlpm._followUpStart))))} | F18: =Definitions!$H$11 -> Medium financial damage | G18: Direct loss, fines for infringements of laws, or violations of contracts below 200,000 EUR Damage level Low | H18: {=CreateID($H$2,$A18<>"")} -> 4 | I18: =IF($Q18="","",_xlfn.LET( _xlpm._in,$Q18, _xlpm._start,FIND("]",_xlpm._in)+1, SUBSTITUTE(MID(_xlpm._in,_xlpm._start,FIND("!",_xlpm._in)-_xlpm._start),"'",""))) | J18: =IF($Q18="","",_xlfn.LET( _xlpm._in,SUBSTITUTE($Q18,"$","§",1), _xlpm._start,FIND("§",_xlpm._in)+1, SUBSTITUTE(MID(_xlpm._in,_xlpm._start,FIND("$",_xlpm._in)-_xlpm._start),"'",""))) | K18: =IF($Q18="","",RIGHT($Q18,LEN($Q18)-FIND("$",SUBSTITUTE($Q18,"$","§",1)))) | L18: {=CreateID($L$2,$I18<>INDEX($I:$I,ROW()-1))} -> 8 | M18: {=IF($Q18="","",INDIRECT($Q18))} | N18: =IF(MOD($H18,2)=0,"D","L") -> D | O18: =IF($A18="",OFFSET($O18,-1,0),$A18) -> QI4
A19: {=IF($Q19="","",_xlfn.LET( _xlpm._fullName,IF($R19="",SUBSTITUTE(SUBSTITUTE(INDIRECT($Q19),CHAR(10)," ")," "," "),$R19), _xlpm._truncatedName,IF(LEN(_xlpm._fullName)>250,LEFT(_xlpm._fullName,250)&"[…]",_xlpm._fullName), HYPERLINK("#'"&$I19&"'!"&$J19&$K19, _xlpm._truncatedName)))} | B19: {=IF($A19="","",SimpleLookup($A19,Questions!$A:$B))} | E19: {=_xlfn.LET( _xlpm._options,IF($O19="","",SimpleLookup($O19,Questions!$A:$H)), _xlpm._followUpStart,FIND($C19&":",_xlpm._options)+LEN($C19&":"), _xlpm._followUpEnd,FIND(CHAR(10),_xlpm._options&CHAR(10),_xlpm._followUpStart), IF($C19="","",TRIM(MID(_xlpm._options,_xlpm._followUpStart,_xlpm._followUpEnd-_xlpm._followUpStart))))} | F19: =Definitions!$H$12 -> High financial damage | G19: Direct loss, fines for infringements of laws, or violations of contracts between 200,000 EUR and 2 million EUR Damage level Medium | H19: {=CreateID($H$2,$A19<>"")} -> 4 | I19: =IF($Q19="","",_xlfn.LET( _xlpm._in,$Q19, _xlpm._start,FIND("]",_xlpm._in)+1, SUBSTITUTE(MID(_xlpm._in,_xlpm._start,FIND("!",_xlpm._in)-_xlpm._start),"'",""))) | J19: =IF($Q19="","",_xlfn.LET( _xlpm._in,SUBSTITUTE($Q19,"$","§",1), _xlpm._start,FIND("§",_xlpm._in)+1, SUBSTITUTE(MID(_xlpm._in,_xlpm._start,FIND("$",_xlpm._in)-_xlpm._start),"'",""))) | K19: =IF($Q19="","",RIGHT($Q19,LEN($Q19)-FIND("$",SUBSTITUTE($Q19,"$","§",1)))) | L19: {=CreateID($L$2,$I19<>INDEX($I:$I,ROW()-1))} -> 8 | M19: {=IF($Q19="","",INDIRECT($Q19))} | N19: =IF(MOD($H19,2)=0,"D","L") -> D | O19: =IF($A19="",OFFSET($O19,-1,0),$A19) -> QI4
A20: {=IF($Q20="","",_xlfn.LET( _xlpm._fullName,IF($R20="",SUBSTITUTE(SUBSTITUTE(INDIRECT($Q20),CHAR(10)," ")," "," "),$R20), _xlpm._truncatedName,IF(LEN(_xlpm._fullName)>250,LEFT(_xlpm._fullName,250)&"[…]",_xlpm._fullName), HYPERLINK("#'"&$I20&"'!"&$J20&$K20, _xlpm._truncatedName)))} | B20: {=IF($A20="","",SimpleLookup($A20,Questions!$A:$B))} | E20: {=_xlfn.LET( _xlpm._options,IF($O20="","",SimpleLookup($O20,Questions!$A:$H)), _xlpm._followUpStart,FIND($C20&":",_xlpm._options)+LEN($C20&":"), _xlpm._followUpEnd,FIND(CHAR(10),_xlpm._options&CHAR(10),_xlpm._followUpStart), IF($C20="","",TRIM(MID(_xlpm._options,_xlpm._followUpStart,_xlpm._followUpEnd-_xlpm._followUpStart))))} | F20: =Definitions!$H$13 -> Critical financial damage | G20: Direct loss, fines for infringements of laws, or violations of contracts between 2 million EUR and 20 million EUR Damage level High | H20: {=CreateID($H$2,$A20<>"")} -> 4 | I20: =IF($Q20="","",_xlfn.LET( _xlpm._in,$Q20, _xlpm._start,FIND("]",_xlpm._in)+1, SUBSTITUTE(MID(_xlpm._in,_xlpm._start,FIND("!",_xlpm._in)-_xlpm._start),"'",""))) | J20: =IF($Q20="","",_xlfn.LET( _xlpm._in,SUBSTITUTE($Q20,"$","§",1), _xlpm._start,FIND("§",_xlpm._in)+1, SUBSTITUTE(MID(_xlpm._in,_xlpm._start,FIND("$",_xlpm._in)-_xlpm._start),"'",""))) | K20: =IF($Q20="","",RIGHT($Q20,LEN($Q20)-FIND("$",SUBSTITUTE($Q20,"$","§",1)))) | L20: {=CreateID($L$2,$I20<>INDEX($I:$I,ROW()-1))} -> 8 | M20: {=IF($Q20="","",INDIRECT($Q20))} | N20: =IF(MOD($H20,2)=0,"D","L") -> D | O20: =IF($A20="",OFFSET($O20,-1,0),$A20) -> QI4
A21: {=IF($Q21="","",_xlfn.LET( _xlpm._fullName,IF($R21="",SUBSTITUTE(SUBSTITUTE(INDIRECT($Q21),CHAR(10)," ")," "," "),$R21), _xlpm._truncatedName,IF(LEN(_xlpm._fullName)>250,LEFT(_xlpm._fullName,250)&"[…]",_xlpm._fullName), HYPERLINK("#'"&$I21&"'!"&$J21&$K21, _xlpm._truncatedName)))} | B21: {=IF($A21="","",SimpleLookup($A21,Questions!$A:$B))} | E21: {=_xlfn.LET( _xlpm._options,IF($O21="","",SimpleLookup($O21,Questions!$A:$H)), _xlpm._followUpStart,FIND($C21&":",_xlpm._options)+LEN($C21&":"), _xlpm._followUpEnd,FIND(CHAR(10),_xlpm._options&CHAR(10),_xlpm._followUpStart), IF($C21="","",TRIM(MID(_xlpm._options,_xlpm._followUpStart,_xlpm._followUpEnd-_xlpm._followUpStart))))} | F21: =Definitions!$H$14 -> Potentially dangerous situation | G21: Direct loss, fines for infringements of laws, or violations of contracts above 20 million EUR, or consequences threatening the company's existence or employees. Damage level Critical | H21: {=CreateID($H$2,$A21<>"")} -> 4 | I21: =IF($Q21="","",_xlfn.LET( _xlpm._in,$Q21, _xlpm._start,FIND("]",_xlpm._in)+1, SUBSTITUTE(MID(_xlpm._in,_xlpm._start,FIND("!",_xlpm._in)-_xlpm._start),"'",""))) | J21: =IF($Q21="","",_xlfn.LET( _xlpm._in,SUBSTITUTE($Q21,"$","§",1), _xlpm._start,FIND("§",_xlpm._in)+1, SUBSTITUTE(MID(_xlpm._in,_xlpm._start,FIND("$",_xlpm._in)-_xlpm._start),"'",""))) | K21: =IF($Q21="","",RIGHT($Q21,LEN($Q21)-FIND("$",SUBSTITUTE($Q21,"$","§",1)))) | L21: {=CreateID($L$2,$I21<>INDEX($I:$I,ROW()-1))} -> 8 | M21: {=IF($Q21="","",INDIRECT($Q21))} | N21: =IF(MOD($H21,2)=0,"D","L") -> D | O21: =IF($A21="",OFFSET($O21,-1,0),$A21) -> QI4
A22: {=IF($Q22="","",_xlfn.LET( _xlpm._fullName,IF($R22="",SUBSTITUTE(SUBSTITUTE(INDIRECT($Q22),CHAR(10)," ")," "," "),$R22), _xlpm._truncatedName,IF(LEN(_xlpm._fullName)>250,LEFT(_xlpm._fullName,250)&"[…]",_xlpm._fullName), HYPERLINK("#'"&$I22&"'!"&$J22&$K22, _xlpm._truncatedName)))} | B22: {=IF($A22="","",SimpleLookup($A22,Questions!$A:$B))} | C22: No | D22: (2) No, in any other case. | E22: {=_xlfn.LET( _xlpm._options,IF($O22="","",SimpleLookup($O22,Questions!$A:$H)), _xlpm._followUpStart,FIND($C22&":",_xlpm._options)+LEN($C22&":"), _xlpm._followUpEnd,FIND(CHAR(10),_xlpm._options&CHAR(10),_xlpm._followUpStart), IF($C22="","",TRIM(MID(_xlpm._options,_xlpm._followUpStart,_xlpm._followUpEnd-_xlpm._followUpStart))))} | H22: {=CreateID($H$2,$A22<>"")} -> 4 | I22: =IF($Q22="","",_xlfn.LET( _xlpm._in,$Q22, _xlpm._start,FIND("]",_xlpm._in)+1, SUBSTITUTE(MID(_xlpm._in,_xlpm._start,FIND("!",_xlpm._in)-_xlpm._start),"'",""))) | J22: =IF($Q22="","",_xlfn.LET( _xlpm._in,SUBSTITUTE($Q22,"$","§",1), _xlpm._start,FIND("§",_xlpm._in)+1, SUBSTITUTE(MID(_xlpm._in,_xlpm._start,FIND("$",_xlpm._in)-_xlpm._start),"'",""))) | K22: =IF($Q22="","",RIGHT($Q22,LEN($Q22)-FIND("$",SUBSTITUTE($Q22,"$","§",1)))) | L22: {=CreateID($L$2,$I22<>INDEX($I:$I,ROW()-1))} -> 8 | M22: {=IF($Q22="","",INDIRECT($Q22))} | N22: =IF(MOD($H22,2)=0,"D","L") -> D | O22: =IF($A22="",OFFSET($O22,-1,0),$A22) -> QI4
A23: {=IF($Q23="","",_xlfn.LET( _xlpm._fullName,IF($R23="",SUBSTITUTE(SUBSTITUTE(INDIRECT($Q23),CHAR(10)," ")," "," "),$R23), _xlpm._truncatedName,IF(LEN(_xlpm._fullName)>250,LEFT(_xlpm._fullName,250)&"[…]",_xlpm._fullName), HYPERLINK("#'"&$I23&"'!"&$J23&$K23, _xlpm._truncatedName)))} -> QI5 | B23: {=IF($A23="","",SimpleLookup($A23,Questions!$A:$B))} -> Does the product contain credentials / cryptographic keys that allow access to sensitive data or to systems in the product's operational environment? (Note: this includes cryptographic data introduced by the customer.) | C23: Yes | D23: (1a) Yes, if credentials are or may be present at runtime that allow access to external systems or external data, for example: * access to PLCs * access to factory networks or databases * access to cloud services * shared service accounts * API keys for external services * network authentication credentials Applies even if: * credentials are customer-configured * credentials are stored temporarily * credentials are encrypted on the device 1b) Yes, if credentials fall under (2*) but are valid beyond a single device, for example: * generic credentials deployed across a fleet of devices * factory-wide authentication keys * service credentials reused on multiple products * certificates or keys not bound to a single device instance | E23: {=_xlfn.LET( _xlpm._options,IF($O23="","",SimpleLookup($O23,Questions!$A:$H)), _xlpm._followUpStart,FIND($C23&":",_xlpm._options)+LEN($C23&":"), _xlpm._followUpEnd,FIND(CHAR(10),_xlpm._options&CHAR(10),_xlpm._followUpStart), IF($C23="","",TRIM(MID(_xlpm._options,_xlpm._followUpStart,_xlpm._followUpEnd-_xlpm._followUpStart))))} -> What is the worst-case criticality of the data that can be accessed with these credentials / cryptographic keys? | G23: Classify the worst credible impact | H23: {=CreateID($H$2,$A23<>"")} -> 5 | I23: =IF($Q23="","",_xlfn.LET( _xlpm._in,$Q23, _xlpm._start,FIND("]",_xlpm._in)+1, SUBSTITUTE(MID(_xlpm._in,_xlpm._start,FIND("!",_xlpm._in)-_xlpm._start),"'",""))) -> Questionnaire | J23: =IF($Q23="","",_xlfn.LET( _xlpm._in,SUBSTITUTE($Q23,"$","§",1), _xlpm._start,FIND("§",_xlpm._in)+1, SUBSTITUTE(MID(_xlpm._in,_xlpm._start,FIND("$",_xlpm._in)-_xlpm._start),"'",""))) -> B | K23: =IF($Q23="","",RIGHT($Q23,LEN($Q23)-FIND("$",SUBSTITUTE($Q23,"$","§",1)))) -> 12 | L23: {=CreateID($L$2,$I23<>INDEX($I:$I,ROW()-1))} -> 9 | M23: {=IF($Q23="","",INDIRECT($Q23))} -> QI5 | N23: =IF(MOD($H23,2)=0,"D","L") -> L | O23: =IF($A23="",OFFSET($O23,-1,0),$A23) -> QI5 | Q23: {=CELL("address",Questionnaire!$B$12)} -> '[QuBA-libre.xlsx]Questionnaire'!$B$12
A24: {=IF($Q24="","",_xlfn.LET( _xlpm._fullName,IF($R24="",SUBSTITUTE(SUBSTITUTE(INDIRECT($Q24),CHAR(10)," ")," "," "),$R24), _xlpm._truncatedName,IF(LEN(_xlpm._fullName)>250,LEFT(_xlpm._fullName,250)&"[…]",_xlpm._fullName), HYPERLINK("#'"&$I24&"'!"&$J24&$K24, _xlpm._truncatedName)))} | B24: {=IF($A24="","",SimpleLookup($A24,Questions!$A:$B))} | E24: {=_xlfn.LET( _xlpm._options,IF($O24="","",SimpleLookup($O24,Questions!$A:$H)), _xlpm._followUpStart,FIND($C24&":",_xlpm._options)+LEN($C24&":"), _xlpm._followUpEnd,FIND(CHAR(10),_xlpm._options&CHAR(10),_xlpm._followUpStart), IF($C24="","",TRIM(MID(_xlpm._options,_xlpm._followUpStart,_xlpm._followUpEnd-_xlpm._followUpStart))))} | F24: =Definitions!$H$8 -> IP (moderately innovative) | G24: Loss of the general idea how solution works or low impact on markets (little innovation / very small market) | H24: {=CreateID($H$2,$A24<>"")} -> 5 | I24: =IF($Q24="","",_xlfn.LET( _xlpm._in,$Q24, _xlpm._start,FIND("]",_xlpm._in)+1, SUBSTITUTE(MID(_xlpm._in,_xlpm._start,FIND("!",_xlpm._in)-_xlpm._start),"'",""))) | J24: =IF($Q24="","",_xlfn.LET( _xlpm._in,SUBSTITUTE($Q24,"$","§",1), _xlpm._start,FIND("§",_xlpm._in)+1, SUBSTITUTE(MID(_xlpm._in,_xlpm._start,FIND("$",_xlpm._in)-_xlpm._start),"'",""))) | K24: =IF($Q24="","",RIGHT($Q24,LEN($Q24)-FIND("$",SUBSTITUTE($Q24,"$","§",1)))) | L24: {=CreateID($L$2,$I24<>INDEX($I:$I,ROW()-1))} -> 10 | M24: {=IF($Q24="","",INDIRECT($Q24))} | N24: =IF(MOD($H24,2)=0,"D","L") -> L | O24: =IF($A24="",OFFSET($O24,-1,0),$A24) -> QI5
A25: {=IF($Q25="","",_xlfn.LET( _xlpm._fullName,IF($R25="",SUBSTITUTE(SUBSTITUTE(INDIRECT($Q25),CHAR(10)," ")," "," "),$R25), _xlpm._truncatedName,IF(LEN(_xlpm._fullName)>250,LEFT(_xlpm._fullName,250)&"[…]",_xlpm._fullName), HYPERLINK("#'"&$I25&"'!"&$J25&$K25, _xlpm._truncatedName)))} | B25: {=IF($A25="","",SimpleLookup($A25,Questions!$A:$B))} | E25: {=_xlfn.LET( _xlpm._options,IF($O25="","",SimpleLookup($O25,Questions!$A:$H)), _xlpm._followUpStart,FIND($C25&":",_xlpm._options)+LEN($C25&":"), _xlpm._followUpEnd,FIND(CHAR(10),_xlpm._options&CHAR(10),_xlpm._followUpStart), IF($C25="","",TRIM(MID(_xlpm._options,_xlpm._followUpStart,_xlpm._followUpEnd-_xlpm._followUpStart))))} | F25: =Definitions!$H$9 -> IP (highly innovative) | G25: Relevant aspects of system is comprehensible or moderate impact on markets (some innovation in the solution / medium size market) | H25: {=CreateID($H$2,$A25<>"")} -> 5 | I25: =IF($Q25="","",_xlfn.LET( _xlpm._in,$Q25, _xlpm._start,FIND("]",_xlpm._in)+1, SUBSTITUTE(MID(_xlpm._in,_xlpm._start,FIND("!",_xlpm._in)-_xlpm._start),"'",""))) | J25: =IF($Q25="","",_xlfn.LET( _xlpm._in,SUBSTITUTE($Q25,"$","§",1), _xlpm._start,FIND("§",_xlpm._in)+1, SUBSTITUTE(MID(_xlpm._in,_xlpm._start,FIND("$",_xlpm._in)-_xlpm._start),"'",""))) | K25: =IF($Q25="","",RIGHT($Q25,LEN($Q25)-FIND("$",SUBSTITUTE($Q25,"$","§",1)))) | L25: {=CreateID($L$2,$I25<>INDEX($I:$I,ROW()-1))} -> 10 | M25: {=IF($Q25="","",INDIRECT($Q25))} | N25: =IF(MOD($H25,2)=0,"D","L") -> L | O25: =IF($A25="",OFFSET($O25,-1,0),$A25) -> QI5
A26: {=IF($Q26="","",_xlfn.LET( _xlpm._fullName,IF($R26="",SUBSTITUTE(SUBSTITUTE(INDIRECT($Q26),CHAR(10)," ")," "," "),$R26), _xlpm._truncatedName,IF(LEN(_xlpm._fullName)>250,LEFT(_xlpm._fullName,250)&"[…]",_xlpm._fullName), HYPERLINK("#'"&$I26&"'!"&$J26&$K26, _xlpm._truncatedName)))} | B26: {=IF($A26="","",SimpleLookup($A26,Questions!$A:$B))} | E26: {=_xlfn.LET( _xlpm._options,IF($O26="","",SimpleLookup($O26,Questions!$A:$H)), _xlpm._followUpStart,FIND($C26&":",_xlpm._options)+LEN($C26&":"), _xlpm._followUpEnd,FIND(CHAR(10),_xlpm._options&CHAR(10),_xlpm._followUpStart), IF($C26="","",TRIM(MID(_xlpm._options,_xlpm._followUpStart,_xlpm._followUpEnd-_xlpm._followUpStart))))} | F26: =Definitions!$H$10 -> Low financial damage | G26: Can be copied / technology available or high impact on markets (highly innovative solution / high-volume market) | H26: {=CreateID($H$2,$A26<>"")} -> 5 | I26: =IF($Q26="","",_xlfn.LET( _xlpm._in,$Q26, _xlpm._start,FIND("]",_xlpm._in)+1, SUBSTITUTE(MID(_xlpm._in,_xlpm._start,FIND("!",_xlpm._in)-_xlpm._start),"'",""))) | J26: =IF($Q26="","",_xlfn.LET( _xlpm._in,SUBSTITUTE($Q26,"$","§",1), _xlpm._start,FIND("§",_xlpm._in)+1, SUBSTITUTE(MID(_xlpm._in,_xlpm._start,FIND("$",_xlpm._in)-_xlpm._start),"'",""))) | K26: =IF($Q26="","",RIGHT($Q26,LEN($Q26)-FIND("$",SUBSTITUTE($Q26,"$","§",1)))) | L26: {=CreateID($L$2,$I26<>INDEX($I:$I,ROW()-1))} -> 10 | M26: {=IF($Q26="","",INDIRECT($Q26))} | N26: =IF(MOD($H26,2)=0,"D","L") -> L | O26: =IF($A26="",OFFSET($O26,-1,0),$A26) -> QI5
